Workbook

Sheet Podsumowanie
A1: WYCENA — „Kielich”: symulator monitora pacjenta (iPad, .NET MAUI)
A2: Aplikacja szkoleniowa (edukacyjna, NIE wyrób medyczny) • Pilot ↔ Monitor • offline P2P • wycena bez instalacji/konfiguracji środowiska • 2026-06-14
A4: ZAŁOŻENIA KLUCZOWE (edytowalne)
A5: Stawka godzinowa | B5: 50 | C5: zł/h
A6: Zarządzanie projektem (PM) | B6: 0.05 | C6: % pracy modułów
A7: Bufor ryzyka / rezerwa | B7: 0.15 | C7: % pracy modułów
A8: Kurs USD → PLN | B8: 4.05 | C8: do przeliczeń licencji
A10: PORÓWNANIE WARIANTÓW
A11: Pozycja | B11: Wariant A — Podstawowy (1:1) | D11: Wariant B — + Opcja 1:N | F11: Wariant C — + reuse II Library (1:1)
B12: Godziny | C12: Koszt | D12: Godziny | E12: Koszt | F12: Godziny | G12: Koszt
A13: Moduły (development + testy) | B13: ='Wycena szczegółowa'!$C$75 | C13: ='Wycena szczegółowa'!$D$75 | D13: ='Wycena szczegółowa'!$C$75+'Opcje dodatkowe'!$C$3 | E13: ='Wycena szczegółowa'!$D$75+'Opcje dodatkowe'!$D$3 | F13: ='Wariant C (reuse)'!$D$18 | G13: ='Wariant C (reuse)'!$E$18
A14: Zarządzanie projektem (PM) | B14: =B13*$B$6 | C14: =B14*$B$5 | D14: =D13*$B$6 | E14: =D14*$B$5 | F14: =F13*$B$6 | G14: =F14*$B$5
A15: Bufor ryzyka / rezerwa | B15: =B13*$B$7 | C15: =B15*$B$5 | D15: =D13*$B$7 | E15: =D15*$B$5 | F15: =F13*$B$7 | G15: =F15*$B$5
A16: RAZEM praca | B16: =SUM(B13:B15) | C16: =SUM(C13:C15) | D16: =SUM(D13:D15) | E16: =SUM(E13:E15) | F16: =SUM(F13:F15) | G16: =SUM(G13:G15)
A17: Koszty stałe (sprzęt, konta, licencje) | B17: — | C17: ='Koszty stałe'!$C$7 | D17: — | E17: ='Koszty stałe'!$C$7 | F17: — | G17: ='Koszty stałe'!$C$7
A18: SUMA CAŁKOWITA | C18: =C16+C17 | E18: =E16+E17 | G18: =G16+G17
A20: Uwagi:
A21: • Wariant B = Wariant A + Opcja A (1:N do 4). Wariant C = Wariant A z ponownym użyciem II Library (Apache 2.0, pełny zakres).
A22: • Wariant C wymaga atrybucji licencyjnej i niesie zależność od cudzego kodu (patrz Ryzyka R11). UI i komunikacja P2P pisane od zera — repo tu nie pomaga.
A23: • PM i bufor liczone od godzin modułów danego wariantu. Koszty stałe identyczne we wszystkich wariantach.
A24: • Dodatkowe iPady do testów 1:N (opcjonalnie) — patrz „Koszty stałe”, poza SUMĄ.
A25: • Opcja B (pełny capture) i Opcja C (Android) — patrz „Opcje dodatkowe”, poza SUMĄ.
A26: • Godziny to pola wejściowe (niebieskie); kwoty liczą się automatycznie ze stawki.

Sheet Wycena szczegółowa
A1: WYCENA SZCZEGÓŁOWA — Wariant A (własny kod), rozbicie na moduły i czynności
A2: Kamień milowy / moduł | B2: Czynność | C2: Godziny | D2: Koszt | E2: Uwagi
A3: M1 — Architektura i komunikacja P2P (APLIKACJA PODSTAWOWA: 2 iPady) | C3: =SUM(C4:C10) | D3: =SUM(D4:D10)
B4: Projekt architektury: warstwy, MVVM, abstrakcja transportu sieciowego pod przyszły Android | C4: 16 | D4: =C4*Podsumowanie!$B$5
B5: Ekran startowy + wybór roli (Pilot / Monitor) | C5: 8 | D5: =C5*Podsumowanie!$B$5
B6: PoC Multipeer Connectivity w MAUI (binding warstwy natywnej, wykrywanie urządzeń) | C6: 24 | D6: =C6*Podsumowanie!$B$5 | E6: Ryzyko R1
B7: Warstwa synchronizacji stanu w czasie rzeczywistym (model danych, protokół, serializacja) | C7: 24 | D7: =C7*Podsumowanie!$B$5
B8: Lista dostępnych Pilotów + wybór bez wpisywania kodu | C8: 10 | D8: =C8*Podsumowanie!$B$5
B9: Obsługa rozłączeń / reconnect + wskaźnik stanu połączenia | C9: 12 | D9: =C9*Podsumowanie!$B$5
B10: Testy komunikacji na 2 fizycznych iPadach | C10: 10 | D10: =C10*Podsumowanie!$B$5 | E10: Wymaga 2 iPadów
A11: M2 — Widok Monitora (silnik przebiegów + parametry) | C11: =SUM(C12:C16) | D11: =SUM(D12:D16)
B12: Silnik renderowania przebiegów (rysowanie, animacja, skala czasu) | C12: 30 | D12: =C12*Podsumowanie!$B$5 | E12: Główny driver kosztów
B13: Przebiegi bazowe: EKG, pleth/SpO₂, ciśnienie tętnicze, CVP/PAP, EtCO₂ | C13: 40 | D13: =C13*Podsumowanie!$B$5
B14: Kolumna parametrów liczbowych (HR, SpO₂, BP, CVP, PAP, EtCO₂, RR, Temp, Timer) | C14: 20 | D14: =C14*Podsumowanie!$B$5
B15: Layout monitora (ciemne tło, czytelność z odległości, układ iPad) | C15: 16 | D15: =C15*Podsumowanie!$B$5
B16: Synchronizacja przebiegów i parametrów z Pilotem | C16: 14 | D16: =C16*Podsumowanie!$B$5
A17: M3 — Pilot: pulpit instruktora | C17: =SUM(C18:C22) | D17: =SUM(D18:D22)
B18: Layout Pilota (podgląd monitora + panel sterowania) | C18: 16 | D18: =C18*Podsumowanie!$B$5
B19: Ręczna zmiana parametrów (kontrolki, walidacja, wysyłka do Monitora) | C19: 24 | D19: =C19*Podsumowanie!$B$5
B20: UI wyboru rytmów i zakłóceń | C20: 16 | D20: =C20*Podsumowanie!$B$5
B21: Podgląd stanu połączenia i statusów | C21: 8 | D21: =C21*Podsumowanie!$B$5
B22: Integracja z warstwą synchronizacji | C22: 12 | D22: =C22*Podsumowanie!$B$5
A23: M4 — Arytmie i zakłócenia (stany przebiegów) | C23: =SUM(C24:C29) | D23: =SUM(D24:D29)
B24: EKG: 17 stanów (bloki, AF, flutter, junctional, LBBB/RBBB, ST elevation, SVT, Torsades, VF, VT, Noise, Disable) | C24: 60 | D24: =C24*Podsumowanie!$B$5 | E24: Wiarygodność = główny driver
B25: EtCO₂: 8 stanów | C25: 16 | D25: =C25*Podsumowanie!$B$5
B26: PAP / CVP: 7 stanów | C26: 16 | D26: =C26*Podsumowanie!$B$5
B27: Arterial / BP: 4 stany | C27: 10 | D27: =C27*Podsumowanie!$B$5
B28: Mechanizm przełączania stanów + wpływ na parametry + synchronizacja | C28: 16 | D28: =C28*Podsumowanie!$B$5
B29: Testy wiarygodności wizualnej | C29: 12 | D29: =C29*Podsumowanie!$B$5
A30: M5 — System scenariuszy | C30: =SUM(C31:C36) | D30: =SUM(D31:D36)
B31: Model danych scenariusza (parametry, rytm, zakłócenia, ustawienia terapii, notatki) | C31: 12 | D31: =C31*Podsumowanie!$B$5
B32: Zapis lokalny (persistencja danych na urządzeniu) | C32: 12 | D32: =C32*Podsumowanie!$B$5
B33: CRUD: tworzenie / edycja / kopiowanie / usuwanie | C33: 24 | D33: =C33*Podsumowanie!$B$5
B34: Edytor scenariuszy (interfejs) | C34: 28 | D34: =C34*Podsumowanie!$B$5
B35: Szybkie uruchamianie + przełączanie scenariuszy w trakcie szkolenia | C35: 16 | D35: =C35*Podsumowanie!$B$5
B36: Testy | C36: 10 | D36: =C36*Podsumowanie!$B$5
A37: M6 — Tryb Defib (defibrylacja) | C37: =SUM(C38:C43) | D37: =SUM(D38:D43)
B38: Widok Defib + lokalne przełączanie widoków Monitor / Defib / AED | C38: 16 | D38: =C38*Podsumowanie!$B$5
B39: Panel wspólny (POWER, ENERGY, CHARGE, SHOCK, DISARM) | C39: 16 | D39: =C39*Podsumowanie!$B$5
B40: Wybór energii 10–360 J + animacja ładowania | C40: 14 | D40: =C40*Podsumowanie!$B$5
...

Sheet Wariant C (reuse)
A1: WARIANT C — ponowne użycie Infirmary Integrated (II Library, Apache 2.0)
A2: Moduł | B2: Godz. własny kod (A) | C2: Korekta reuse | D2: Godz. Wariant C | E2: Koszt (C) | F2: Uwaga
A3: M1 — Architektura i komunikacja P2P | B3: ='Wycena szczegółowa'!C3 | C3: 0 | D3: =B3+C3 | E3: =D3*Podsumowanie!$B$5
A4: M2 — Widok Monitora | B4: ='Wycena szczegółowa'!C11 | C4: -40 | D4: =B4+C4 | E4: =D4*Podsumowanie!$B$5 | F4: Reuse silnika fal i przebiegów z II Library
A5: M3 — Pilot: pulpit instruktora | B5: ='Wycena szczegółowa'!C17 | C5: 0 | D5: =B5+C5 | E5: =D5*Podsumowanie!$B$5
A6: M4 — Arytmie i zakłócenia | B6: ='Wycena szczegółowa'!C23 | C6: -60 | D6: =B6+C6 | E6: =D6*Podsumowanie!$B$5 | F6: Reuse 30+ rytmów z II Library (największa oszczędność)
A7: M5 — System scenariuszy | B7: ='Wycena szczegółowa'!C30 | C7: -20 | D7: =B7+C7 | E7: =D7*Podsumowanie!$B$5 | F7: Reuse modelu danych scenariusza
A8: M6 — Tryb Defib | B8: ='Wycena szczegółowa'!C37 | C8: -10 | D8: =B8+C8 | E8: =D8*Podsumowanie!$B$5 | F8: Reuse logiki defibrylacji
A9: M7 — Tryb AED | B9: ='Wycena szczegółowa'!C44 | C9: -8 | D9: =B9+C9 | E9: =D9*Podsumowanie!$B$5 | F9: Reuse logiki AED
A10: M8 — Kardiowersja zsynchronizowana | B10: ='Wycena szczegółowa'!C49 | C10: -8 | D10: =B10+C10 | E10: =D10*Podsumowanie!$B$5 | F10: Reuse logiki kardiowersji
A11: M9 — Stymulacja | B11: ='Wycena szczegółowa'!C54 | C11: -10 | D11: =B11+C11 | E11: =D11*Podsumowanie!$B$5 | F11: Reuse logiki pacingu
A12: M10 — Logika wyładowań i zmiany rytmu | B12: ='Wycena szczegółowa'!C59 | C12: 0 | D12: =B12+C12 | E12: =D12*Podsumowanie!$B$5
A13: M11 — Ustawienia | B13: ='Wycena szczegółowa'!C64 | C13: 0 | D13: =B13+C13 | E13: =D13*Podsumowanie!$B$5
A14: M12 — Testy, stabilizacja, UX, dystrybucja | B14: ='Wycena szczegółowa'!C69 | C14: 0 | D14: =B14+C14 | E14: =D14*Podsumowanie!$B$5
A15: Dodatkowa praca konieczna przy reuse
A16: Port II Library do MAUI (usunięcie zależności desktopowych, refaktor) | B16: — | C16: — | D16: 40 | E16: =D16*Podsumowanie!$B$5
A17: Obsługa licencji Apache 2.0 (atrybucja, NOTICE, zgodność) | B17: — | C17: — | D17: 4 | E17: =D17*Podsumowanie!$B$5 | F17: Wymóg licencji
A18: RAZEM moduły — Wariant C | D18: =SUM(D3:D17) | E18: =SUM(E3:E17)

Sheet Opcje dodatkowe
A1: OPCJE DODATKOWE — praca poza zakresem podstawowym
A2: Opcja / moduł | B2: Czynność | C2: Godziny | D2: Koszt | E2: Uwagi
A3: OPCJA A — Połączenie 1:N (1 Pilot → do 4 Monitorów) | C3: =SUM(C4:C8) | D3: =SUM(D4:D8)
B4: Rozszerzenie warstwy synchronizacji na wielu klientów (broadcast, sesje per-urządzenie) | C4: 30 | D4: =C4*Podsumowanie!$B$5
B5: Pulpit master: lista klientów, wybór celu sterowania, podgląd wielu Monitorów | C5: 40 | D5: =C5*Podsumowanie!$B$5 | E5: Nowe ekrany Pilota
B6: Zarządzanie sesjami wielu urządzeń (dołączanie / odłączanie / nazwy) | C6: 20 | D6: =C6*Podsumowanie!$B$5
B7: Testy z 4+ urządzeniami (stabilność, wydajność P2P) | C7: 24 | D7: =C7*Podsumowanie!$B$5 | E7: Wymaga dodatkowych iPadów
B8: Bufor ryzyka multi-peer (Multipeer przy wielu klientach) | C8: 16 | D8: =C8*Podsumowanie!$B$5 | E8: Ryzyka R1/R6
A9: OPCJA B — Pełny model capture/no-capture w Pacingu | C9: =SUM(C10:C10) | D9: =SUM(D10:D10)
B10: Zaawansowana logika progu wychwycenia (mA/rate) zamiast modelu uproszczonego | C10: 24 | D10: =C10*Podsumowanie!$B$5 | E10: Alternatywa dla M9
A12: OPCJA C — Port na Android (przyszłość, orientacyjnie)
A13: Dzięki .NET MAUI i abstrakcji transportu (M1) logika/UI są w dużej mierze współdzielone. Główna praca: natywna warstwa P2P na Androidzie (Nearby Connections zamiast Multipeer), testy na sprzęcie Android, zgodność layoutów. Orientacyjnie 120–180 h. NIE wliczane do sum.

Sheet Koszty stałe
A1: KOSZTY STAŁE — sprzęt, konta, licencje
A2: Pozycja | B2: Ilość | C2: Koszt (zł) | D2: Uwaga
A3: Mac (host budowania iOS) — WYMAGANY | B3: 1 | C3: 0 | D3: Klient posiada — 0 zł. Bez Maca: ~2 500–3 500 zł (Mac mini).
A4: Apple Developer Program (rocznie) | B4: 1 | C4: =ROUND(99*Podsumowanie!$B$8,0) | D4: 99 USD/rok. Wymagany do TestFlight i podpisywania.
A5: iPad (model docelowy) — sprzęt FIZYCZNY | B5: 2 | C5: 5000 | D5: Klient NIE posiada. ~2 500 zł/szt. Min. 2 do testów P2P.
A6: Akcesoria (etui, ładowarki, kable USB-C) | B6: 1 | C6: 300 | D6: Szacunkowo.
A7: RAZEM koszty stałe (wszystkie warianty) | C7: =C3+C4+C5+C6
A8: Dodatkowe iPady do testów 1:N (opcjonalnie) | B8: 2 | C8: 5000 | D8: Do rzetelnych testów 1 Pilot → 4 Monitory. Można wypożyczyć — stąd jako opcja, poza sumą.

Sheet Ryzyka
A1: REJESTR RYZYK I ZAGROŻEŃ
A2: ID | B2: Ryzyko | C2: Prawdop. | D2: Wpływ | E2: Działanie ograniczające (mitygacja)
A3: R1 | B3: Multipeer Connectivity w .NET MAUI wymaga własnego bindingu warstwy natywnej | C3: Wysokie | D3: Wysoki | E3: PoC w M1 jako pierwszy krok; plan B: lokalna sieć TCP/UDP. Bufor 15%.
A4: R2 | B4: Brak doświadczenia programisty z Apple/iOS (Xcode, podpisywanie, provisioning) | C4: Wysokie | D4: Średni | E4: Pomoc materiałów; TestFlight zamiast App Store ogranicza tarcia.
A5: R3 | B5: Wiarygodność wizualna przebiegów EKG/arytmii trudniejsza niż zakładano | C5: Średnie | D5: Wysoki | E5: Najpierw silnik (M2), potem stany (M4); Wariant C mocno to ogranicza (reuse).
A6: R4 | B6: Uwagi/odrzucenie Apple (aplikacja „okołomedyczna”) | C6: Średnie | D6: Średni | E6: TestFlight/wewnętrznie; oznaczenie „symulacja edukacyjna, nie wyrób medyczny”.
A7: R5 | B7: Stabilność synchronizacji w czasie rzeczywistym (opóźnienia, desync) | C7: Średnie | D7: Wysoki | E7: Prosty, odporny protokół; reconnect; testy na realnym sprzęcie.
A8: R6 | B8: Skalowanie 1:N (do 4) — wydajność i stabilność Multipeer | C8: Średnie | D8: Średni | E8: Bufor w Opcji A; testy z 4+ urządzeniami; limit 4 klientów.
A9: R7 | B9: Brak fizycznych iPadów = brak realnych testów P2P | C9: Wysokie | D9: Wysoki | E9: Zakup min. 2 iPadów (Koszty stałe) na starcie.
A10: R8 | B10: Niedoszacowanie zakresu „pełna wersja, nie MVP” | C10: Średnie | D10: Wysoki | E10: Kamienie milowe; przyrostowe dostarczanie; rezerwa 15%.
A11: R9 | B11: Zależność od jednego programisty | C11: Średnie | D11: Wysoki | E11: Dokumentacja na bieżąco; repo pod kontrolą wersji.
A12: R10 | B12: Złożoność audio (AED, metronom, alarmy) na iPadOS | C12: Niskie | D12: Niski | E12: Standardowe API audio; wczesny prototyp.
A13: R11 | B13: [Wariant C] Zależność od kodu II Library: zrozumienie/utrzymanie cudzego kodu, zgodność z Apache 2.0 | C13: Średnie | D13: Średni | E13: Doliczony czas na analizę i port; dołączenie licencji/NOTICE; możliwość fork-a.

Sheet Założenia
A1: ZAŁOŻENIA I ZAKRES WYCENY
A3: 1 | B3: Technologia: .NET MAUI (C#), Visual Studio + VS Code. Architektura przygotowana pod przyszły Android.
A4: 2 | B4: WYCENA NIE OBEJMUJE instalacji środowiska, instalacji narzędzi ani konfiguracji — tylko czas developmentu.
A5: 3 | B5: Mac jako host budowania iOS jest WYMAGANY (kompilacja i podpisywanie) — klient posiada.
A6: 4 | B6: Programista: 1 osoba, C#/.NET (web), bez doświadczenia z Apple/iOS.
A7: 5 | B7: Stawka: 50 zł/h (edytowalna). Wszystkie kwoty = godziny × stawka.
A8: 6 | B8: Zakres = pełna wersja produktu (nie MVP), dostarczana przyrostowo M1→M12.
A9: 7 | B9: Komunikacja offline P2P (Multipeer Connectivity lub równoważne); brak internetu/serwera.
A10: 8 | B10: Role: Pilot (instruktor) steruje; Monitor (kursant) wyświetla i lokalnie przełącza Monitor/Defib/AED.
A11: 9 | B11: Dystrybucja: TestFlight / wewnętrzna. Apple Developer Program 99 USD/rok.
A12: 10 | B12: Wariant A = własny kod (clean-room). Wariant B = A + 1:N (do 4). Wariant C = A z reuse II Library.
A13: 11 | B13: Wariant C: ponowne użycie II Library (Apache 2.0) z atrybucją; UI i komunikacja P2P pisane od zera.
A14: 12 | B14: Pacing: w zakresie podstawowym model UPROSZCZONY; pełny = Opcja B.
... A17: 15 | B17: Godziny szacunkowe; realny czas zależy m.in. od wyniku PoC komunikacji P2P (M1).
